Workbook
Name compte: 'Bilan ouverture'!$A$18:$A$49
Name comptes: 'Bilan ouverture'!$A$18:$A$50
Name date: Journal!$O$1:$O$365
Name Deb: Membres!$A$6

Sheet Menu
D6: Comptabilité pour Association

Sheet Bilan ouverture
A1: Bilan d'ouverture d'exercice
B2: Actifs | C2: Montant | E2: Passifs | F2: Montant
B3: commentaires
A4: 1000 | B4: Caisse | D4: 2010 | E4: Charges à payer et avance à rembourser
A5: 1020 | B5: Banque | C5: 333.44 | D5: 2400 | E5: Dettes bancaires ou autres emprunts
A6: 1300 | B6: Actifs transitoires | D6: 2300 | E6: Passifs transitoires
A7: 1110 | B7: Cotisation en attente des membres | D7: 2950 | E7: Résultat reporté
A8: 1208 | B8: Diverses cautions versées | D8: 9000 | E8: Résultat | F8: 333.44
A9: 1500 | B9: Actifs ex meuble | D9: 2800 | E9: Capital ou fond déposé en banque
A10: 1530 | B10: Actifs ex véhicule
A12: Totaux | C12: =SUM(C4:C9) -> 333.44 | F12: =SUM(F4:F9) -> 333.44
A13: =IF(C12-F12=0,"Votre bilan d'ouverture est équilibré vous pouvez poursuivre"," Déséquilibre de votre bilan d'ouverture , Equilibrer le bilan en observant l'écart actifs -passifs avant de poursuivre") -> Votre bilan d'ouverture est équilibré vous pouvez poursuivre | F13: =F12-C12 -> 0
A17: Les Comptes
A18: =A4 -> 1000 | B18: =B4 -> Caisse
A19: =A5 -> 1020 | B19: =B5 -> Banque
A20: =A6 -> 1300 | B20: =B6 -> Actifs transitoires
A21: =A7 -> 1110 | B21: =B7 -> Cotisation en attente des membres
A22: =A8 -> 1208 | B22: =B8 -> Diverses cautions versées
A23: =A9 -> 1500 | B23: =B9 -> Actifs ex meuble
A24: =A10 -> 1530 | B24: =B10 -> Actifs ex véhicule
A25: =D4 -> 2010 | B25: =E4 -> Charges à payer et avance à rembourser
A26: =D5 -> 2400 | B26: =E5 -> Dettes bancaires ou autres emprunts
A27: =D6 -> 2300 | B27: =E6 -> Passifs transitoires
A28: =D7 -> 2950 | B28: =E7 -> Résultat reporté
A29: =D8 -> 9000 | B29: =E8 -> Résultat
A30: =D9 -> 2800 | B30: =E9 -> Capital ou fond déposé en banque
A31: =Résultat!A6 -> 454000 | B31: =Résultat!B6 -> Frais bénévoles PP ONSS
A32: =Résultat!A7 -> 611000 | B32: =Résultat!B7 -> Loyer
A33: =Résultat!A8 -> 611100 | B33: =Résultat!B8 -> Electricité, gaz
A34: =Résultat!A9 -> 611200 | B34: =Résultat!B9 -> Charges Divers
A35: =Résultat!A10 -> 611500 | B35: =Résultat!B10 -> Frais d'expéditions et Pub
A36: =Résultat!A11 -> 614000 | B36: =Résultat!B11 -> Divers assurances
A37: =Résultat!A12 -> 621000 | B37: =Résultat!B12 -> Salaire
A38: =Résultat!A13 -> 613000 | B38: =Résultat!B13 -> Divers frais administratifs
A39: =Résultat!A14 -> 618000 | B39: =Résultat!B14 -> Frais Bénévoles
A40: =Résultat!A15 -> 670000 | B40: =Résultat!B15 -> ACE / mali de caisse
A41: =Résultat!A16 -> 630000 | B41: =Résultat!B16 -> Amortissement actifs
A42: =Résultat!A17 -> 657000 | B42: =Résultat!B17 -> Frais et charges financiers
A43: =Résultat!A18 -> 140000 | B43: =Résultat!B18 -> Résultat avant affectation
A44: =Résultat!D12 -> 3201 | B44: =Résultat!E12 -> Subventions obtenues projet 1
...

Sheet Journal
A1: Journal des écritures quotidiennes | D1: votre résultat actuelle | G1: =Résultat!C18 -> -74933.8 | O1: =G2 -> 44562
A2: Comptes bilan | B2: =IF(C2="","",VLOOKUP(C2,'Bilan Clôture'!A14:F45,2,0)) -> Caisse | C2: 1000 | D2: =ABS(IF(C2="","",VLOOKUP(C2,'Bilan Clôture'!A50:C63,3,0))) -> 0 | E2: =IF('Bilan Clôture'!F11='Bilan Clôture'!C11,"Equilibre du bilan de clôture", "Deséquilibre du bilan de clôture, Vérifier les dernières écritures") -> Equilibre du bilan de clôture | F2: Date de debut d'exercice | G2: 44562 | O2: =O1+1 -> 44563
A3: Dates | B3: Libellés | C3: Compte débité | D3: Compte crédité | E3: Montants | F3: Vérif compte débité | G3: Vérif compte crédité | O3: =O2+1 -> 44564
A4: 44926 | B4: Benevole | C4: 618000 | E4: 0 | F4: Frais Bénévoles | G4: =IF(D4="","",VLOOKUP(D4,'Bilan ouverture'!$A$18:$B$49,2,0)) | O4: =O3+1 -> 44565
A5: 44926 | B5: Loyer | C5: 611000 | E5: =101+39+2562.5+90+4375 -> 7167.5 | F5: Loyer | G5: =IF(D5="","",VLOOKUP(D5,'Bilan ouverture'!$A$18:$B$49,2,0)) | O5: =O4+1 -> 44566
A6: 44926 | B6: Electrabel | C6: 611100 | E6: 0 | F6: Electricité, gaz | G6: =IF(D6="","",VLOOKUP(D6,'Bilan ouverture'!$A$18:$B$49,2,0)) | O6: =O5+1 -> 44567
A7: 44926 | B7: banque | C7: 657000 | E7: =11.25+16.34+10.89+11.25+12.71+11.25+3.63 -> 77.32 | F7: Frais et charges financiers | G7: =IF(D7="","",VLOOKUP(D7,'Bilan ouverture'!$A$18:$B$49,2,0)) | O7: =O6+1 -> 44568
A8: 44926 | B8: Rentrer | D8: 700000 | E8: =1250+2100+1824.5+1250+1360+2300+1000+300+28+875+4250+450+450+875+400+500+215+150+400+300+350+150+100+100+4375+330+400+1050-130+350+432+250+250+160+790+800+1030+445+500+500+1000+2650+1950+1695+2575+1022+296+1900+1400+722+318+2200+1201+1675+1425 -> 54538.5 | G8: Chiffre d'affaire | O8: =O7+1 -> 44569
A9: 44926 | B9: Charges divers | C9: 611200 | E9: =1269+11972.03+3613.06+544.5+155.7+4670.18+4049.26+272.25+147+11695.84+2694.66+5812.6+465.9+13.99+4375+10+431.14+540.19+1051.23+526.78 -> 54310.31 | G9: =IF(D9="","",VLOOKUP(D9,'Bilan ouverture'!$A$18:$B$49,2,0)) | O9: =O8+1 -> 44570
A10: 44926 | B10: Assurance | C10: 614000 | F10: Divers assurances | G10: =IF(D10="","",VLOOKUP(D10,'Bilan ouverture'!$A$18:$B$49,2,0)) | O10: =O9+1 -> 44571
A11: 44926 | B11: ONSS | C11: 454000 | F11: =IF(C11="","",VLOOKUP(C11,'Bilan ouverture'!$A$18:$B$49,2,0)) -> Frais bénévoles PP ONSS | G11: =IF(D11="","",VLOOKUP(D11,'Bilan ouverture'!$A$18:$B$49,2,0)) | O11: =O10+1 -> 44572
A12: 44926 | B12: salaire | C12: 621000 | E12: =250+125+180+87.5+150+190+450+285+78.5+216+190+180+60+125+137.5+210+170+175+60.8+100+400+225+600+290+400+450+120+285+290+380+140+1000 -> 8000.3 | F12: =IF(C12="","",VLOOKUP(C12,'Bilan ouverture'!$A$18:$B$49,2,0)) -> Salaire | G12: =IF(D12="","",VLOOKUP(D12,'Bilan ouverture'!$A$18:$B$49,2,0)) | O12: =O11+1 -> 44573
A13: 44926 | B13: Charges divers | C13: 611200 | E13: =443.48+504.03+526.78+431.14+121.6+309.67+459.43+540.19+600.32+62.66+91.56+0.77+465.9+152.36+443.48+225 -> 5378.37 | F13: 12065,4/4 invest | G13: =IF(D13="","",VLOOKUP(D13,'Bilan ouverture'!$A$18:$B$49,2,0)) | O13: =O12+1 -> 44574
A14: 44926 | B14: Rentrer | D14: 700000 | E14: =2086+650+1178+1650+1100+150+850+2650+2900+764+1058+1950+1050+1265+950 -> 20251 | G14: Chiffre d'affaire | O14: =O13+1 -> 44575
A15: 44926 | F15: =IF(C15="","",VLOOKUP(C15,'Bilan ouverture'!$A$18:$B$49,2,0)) | G15: =IF(D15="","",VLOOKUP(D15,'Bilan ouverture'!$A$18:$B$49,2,0)) | O15: =O14+1 -> 44576
A16: 44926 | F16: =IF(C16="","",VLOOKUP(C16,'Bilan ouverture'!$A$18:$B$49,2,0)) | G16: =IF(D16="","",VLOOKUP(D16,'Bilan ouverture'!$A$18:$B$49,2,0)) | O16: =O15+1 -> 44577
F17: =IF(C17="","",VLOOKUP(C17,'Bilan ouverture'!$A$18:$B$49,2,0)) | G17: =IF(D17="","",VLOOKUP(D17,'Bilan ouverture'!$A$18:$B$49,2,0)) | O17: =O16+1 -> 44578
E18: =E8+E14 -> 74789.5 | F18: =IF(C18="","",VLOOKUP(C18,'Bilan ouverture'!$A$18:$B$49,2,0)) | G18: =IF(D18="","",VLOOKUP(D18,'Bilan ouverture'!$A$18:$B$49,2,0)) | O18: =O17+1 -> 44579
F19: =IF(C19="","",VLOOKUP(C19,'Bilan ouverture'!$A$18:$B$49,2,0)) | G19: =IF(D19="","",VLOOKUP(D19,'Bilan ouverture'!$A$18:$B$49,2,0)) | O19: =O18+1 -> 44580
F20: =IF(C20="","",VLOOKUP(C20,'Bilan ouverture'!$A$18:$B$49,2,0)) | G20: =IF(D20="","",VLOOKUP(D20,'Bilan ouverture'!$A$18:$B$49,2,0)) | O20: =O19+1 -> 44581
F21: =IF(C21="","",VLOOKUP(C21,'Bilan ouverture'!$A$18:$B$49,2,0)) | G21: =IF(D21="","",VLOOKUP(D21,'Bilan ouverture'!$A$18:$B$49,2,0)) | O21: =O20+1 -> 44582
F22: =IF(C22="","",VLOOKUP(C22,'Bilan ouverture'!$A$18:$B$49,2,0)) | G22: =IF(D22="","",VLOOKUP(D22,'Bilan ouverture'!$A$18:$B$49,2,0)) | O22: =O21+1 -> 44583
F23: =IF(C23="","",VLOOKUP(C23,'Bilan ouverture'!$A$18:$B$49,2,0)) | G23: =IF(D23="","",VLOOKUP(D23,'Bilan ouverture'!$A$18:$B$49,2,0)) | O23: =O22+1 -> 44584
F24: =IF(C24="","",VLOOKUP(C24,'Bilan ouverture'!$A$18:$B$49,2,0)) | G24: =IF(D24="","",VLOOKUP(D24,'Bilan ouverture'!$A$18:$B$49,2,0)) | O24: =O23+1 -> 44585
F25: =IF(C25="","",VLOOKUP(C25,'Bilan ouverture'!$A$18:$B$49,2,0)) | G25: =IF(D25="","",VLOOKUP(D25,'Bilan ouverture'!$A$18:$B$49,2,0)) | O25: =O24+1 -> 44586
F26: =IF(C26="","",VLOOKUP(C26,'Bilan ouverture'!$A$18:$B$49,2,0)) | G26: =IF(D26="","",VLOOKUP(D26,'Bilan ouverture'!$A$18:$B$49,2,0)) | O26: =O25+1 -> 44587
F27: =IF(C27="","",VLOOKUP(C27,'Bilan ouverture'!$A$18:$B$49,2,0)) | G27: =IF(D27="","",VLOOKUP(D27,'Bilan ouverture'!$A$18:$B$49,2,0)) | O27: =O26+1 -> 44588
F28: =IF(C28="","",VLOOKUP(C28,'Bilan ouverture'!$A$18:$B$49,2,0)) | G28: =IF(D28="","",VLOOKUP(D28,'Bilan ouverture'!$A$18:$B$49,2,0)) | O28: =O27+1 -> 44589
F29: =IF(C29="","",VLOOKUP(C29,'Bilan ouverture'!$A$18:$B$49,2,0)) | G29: =IF(D29="","",VLOOKUP(D29,'Bilan ouverture'!$A$18:$B$49,2,0)) | O29: =O28+1 -> 44590
F30: =IF(C30="","",VLOOKUP(C30,'Bilan ouverture'!$A$18:$B$49,2,0)) | G30: =IF(D30="","",VLOOKUP(D30,'Bilan ouverture'!$A$18:$B$49,2,0)) | O30: =O29+1 -> 44591
... F102: =IF(C102="","",VLOOKUP(C102,'Bilan ouverture'!$A$18:$B$49,2,0)) | G102: =IF(D102="","",VLOOKUP(D102,'Bilan ouverture'!$A$18:$B$49,2,0)) | O102: =O101+1 -> 44663
O103: =O102+1 -> 44664
O104: =O103+1 -> 44665
O105: =O104+1 -> 44666
O106: =O105+1 -> 44667
O107: =O106+1 -> 44668
O108: =O107+1 -> 44669
O109: =O108+1 -> 44670
O110: =O109+1 -> 44671
O111: =O110+1 -> 44672
...

Sheet Résultat
B2: Compte d'exploitation ou Résultat
B4: Charges | C4: Montants | E4: Produits | F4: Montants
A6: 454000 | B6: Frais bénévoles PP ONSS | C6: ='Bilan Clôture'!F27 -> 0
A7: 611000 | B7: Loyer | C7: ='Bilan Clôture'!F28 -> 7167.5
A8: 611100 | B8: Electricité, gaz | C8: ='Bilan Clôture'!F29 -> 0
A9: 611200 | B9: Charges Divers | C9: ='Bilan Clôture'!F30 -> 59688.68
A10: 611500 | B10: Frais d'expéditions et Pub | C10: ='Bilan Clôture'!F31 -> 0
A11: 614000 | B11: Divers assurances | C11: ='Bilan Clôture'!F32 -> 0
A12: 621000 | B12: Salaire | C12: ='Bilan Clôture'!F33 -> 8000.3 | D12: 3201 | E12: Subventions obtenues projet 1 | F12: =-'Bilan Clôture'!F39 -> 0
A13: 613000 | B13: Divers frais administratifs | C13: ='Bilan Clôture'!F34 -> 0 | D13: 3202 | E13: Subventions obtenues projet 2 | F13: =-'Bilan Clôture'!F40 -> 0
A14: 618000 | B14: Frais Bénévoles | C14: ='Bilan Clôture'!F35 -> 0 | D14: 3203 | E14: Subventions obtenues projet 3 | F14: =-'Bilan Clôture'!F41 -> 0
A15: 670000 | B15: ACE / mali de caisse | C15: ='Bilan Clôture'!F36 -> 0 | D15: 3400 | E15: Subventions non affectées obtenues | F15: =-'Bilan Clôture'!F42 -> 0
A16: 630000 | B16: Amortissement actifs | C16: ='Bilan Clôture'!F37 -> 0 | D16: 3600 | E16: Cotisations payées par les membres | F16: =-'Bilan Clôture'!F43 -> 0
A17: 657000 | B17: Frais et charges financiers | C17: ='Bilan Clôture'!F38 -> 77.32 | D17: 3630 | E17: Dons et legs obtenus / boni de caisse | F17: =-'Bilan Clôture'!F44 -> 0
A18: 140000 | B18: Résultat avant affectation | C18: =SUM(F12:F18)-SUM(C6:C17) -> -74933.8 | D18: 700000 | E18: Paiement Parents | F18: =-'Bilan Clôture'!F45 -> 0
B19: Total | C19: =SUM(C6:C18) -> 0 | F19: =SUM(F10:F18) -> 0

Sheet Caisse
A1: Tenue de caisse
A3: Nom / Prénom
A5: Date | C5: Heures
A7: Billets | B7: Nombres | C7: x | D7: Billets | E7: = | F7: Totaux
B9: 0 | C9: x | D9: 200 | E9: = | F9: =PRODUCT(B9,D9) -> 0
B10: 0 | C10: x | D10: 100 | E10: = | F10: =PRODUCT(B10,D10) -> 0
B11: 0 | C11: x | D11: 50 | E11: = | F11: =PRODUCT(B11,D11) -> 0
B12: 0 | C12: x | D12: 20 | E12: = | F12: =PRODUCT(B12,D12) -> 0
B13: 0 | C13: x | D13: 10 | E13: = | F13: =PRODUCT(B13,D13) -> 0
A15: Monnaie | B15: Nombres | C15: x | D15: Pieces | F15: Totaux
B17: 0 | C17: x | D17: 5 | E17: = | F17: =PRODUCT(B17,D17) -> 0
B18: 0 | C18: x | D18: 2 | E18: = | F18: =PRODUCT(B18,D18) -> 0
B19: 0 | C19: x | D19: 1 | E19: = | F19: =PRODUCT(B19,D19) -> 0
B20: 0 | C20: x | D20: 0.5 | E20: = | F20: =PRODUCT(B20,D20) -> 0
B21: 0 | C21: x | D21: 0.2 | E21: = | F21: =PRODUCT(B21,D21) -> 0
B22: 0 | C22: x | D22: 0.1 | E22: = | F22: =PRODUCT(B22,D22) -> 0
B23: 0 | C23: x | D23: 0.05 | E23: = | F23: =PRODUCT(B23,D23) -> 0
B25: Total | F25: =SUM(F9:F24) -> 0
B27: Fonds de caisse | D27: =F25 -> 0 | F27: =D27 -> 0
A29: Recette journalière
A31: Nom / Prénom
A33: Date | C33: Heures
A35: Billets | B35: Nombres | C35: x | D35: Billets | E35: = | F35: Totaux
B37: 0 | C37: x | D37: 200 | E37: = | F37: =PRODUCT(B37,D37) -> 0
B38: 0 | C38: x | D38: 100 | E38: = | F38: =PRODUCT(B38,D38) -> 0
B39: 0 | C39: x | D39: 50 | E39: = | F39: =PRODUCT(B39,D39) -> 0
B40: 0 | C40: x | D40: 20 | E40: = | F40: =PRODUCT(B40,D40) -> 0
B41: 0 | C41: x | D41: 10 | E41: = | F41: =PRODUCT(B41,D41) -> 0
A43: Monnaie | B43: Nombres | C43: x | D43: Pieces | F43: Totaux
B45: 0 | C45: x | D45: 5 | E45: = | F45: =PRODUCT(B45,D45) -> 0
B46: 0 | C46: x | D46: 2 | E46: = | F46: =PRODUCT(B46,D46) -> 0
B47: 0 | C47: x | D47: 1 | E47: = | F47: =PRODUCT(B47,D47) -> 0
B48: 0 | C48: x | D48: 0.5 | E48: = | F48: =PRODUCT(B48,D48) -> 0
B49: 0 | C49: x | D49: 0.2 | E49: = | F49: =PRODUCT(B49,D49) -> 0
B50: 0 | C50: x | D50: 0.1 | E50: = | F50: =PRODUCT(B50,D50) -> 0
B51: 0 | C51: x | D51: 0.05 | E51: = | F51: =PRODUCT(B51,D51) -> 0
B53: Recette du jour | F53: =SUM(F37:F52) -> 0
B55: Fonds de caisse initial | D55: =F27 -> 0
B56: Recettes nettes | F56: =F53-D55 -> 0

Sheet Bilan Clôture
B2: Actifs | C2: Montant | E2: Passifs | F2: Montant
A3: N0 | B3: Comptes | D3: N0 | E3: Comptes
A4: ='Bilan ouverture'!A4 -> 1000 | B4: ='Bilan ouverture'!B4 -> Caisse | C4: ='Bilan ouverture'!C4+F14 -> 0 | D4: ='Bilan ouverture'!D4 -> 2010 | E4: ='Bilan ouverture'!E4 -> Charges à payer et avance à rembourser | F4: ='Bilan ouverture'!F4-F21 -> 0
A5: ='Bilan ouverture'!A5 -> 1020 | B5: ='Bilan ouverture'!B5 -> Banque | D5: ='Bilan ouverture'!D5 -> 2400 | E5: ='Bilan ouverture'!E5 -> Dettes bancaires ou autres emprunts | F5: ='Bilan ouverture'!F5-F22 -> 0
A6: ='Bilan ouverture'!A6 -> 1300 | B6: ='Bilan ouverture'!B6 -> Actifs transitoires | C6: ='Bilan ouverture'!C6+F16 -> 0 | D6: ='Bilan ouverture'!D6 -> 2300 | E6: ='Bilan ouverture'!E6 -> Passifs transitoires | F6: ='Bilan ouverture'!F6-F23 -> 0
A7: ='Bilan ouverture'!A7 -> 1110 | B7: ='Bilan ouverture'!B7 -> Cotisation en attente des membres | C7: ='Bilan ouverture'!C7+F17 -> 0 | D7: ='Bilan ouverture'!D7 -> 2950 | E7: ='Bilan ouverture'!E7 -> Résultat reporté | F7: ='Bilan ouverture'!F7-F24 -> 0
A8: ='Bilan ouverture'!A8 -> 1208 | B8: ='Bilan ouverture'!B8 -> Diverses cautions versées | C8: ='Bilan ouverture'!C8+F18 -> 0 | D8: ='Bilan ouverture'!D8 -> 9000 | E8: ='Bilan ouverture'!E8 -> Résultat | F8: 0
A9: ='Bilan ouverture'!A9 -> 1500 | B9: ='Bilan ouverture'!B9 -> Actifs ex meuble | C9: ='Bilan ouverture'!C9+F19 -> 0 | D9: ='Bilan ouverture'!D9 -> 2800 | E9: ='Bilan ouverture'!E9 -> Capital ou fond déposé en banque | F9: ='Bilan ouverture'!F9-F26 -> 0
A10: ='Bilan ouverture'!A10 -> 1530 | B10: ='Bilan ouverture'!B10 -> Actifs ex véhicule | C10: ='Bilan ouverture'!C10+F20 -> 0
B11: Total | C11: =SUM(C4:C10) -> 0 | E11: Total
A14: ='Bilan ouverture'!A18 -> 1000 | B14: ='Bilan ouverture'!B18 -> Caisse | C14: =SUMIF(Journal!$C$4:$C$215,A14,Journal!$E$4:$E$215) -> 0 | E14: =SUMIF(Journal!$D$4:$D$215,A14,Journal!$E$4:$E$215) -> 0 | F14: =C14-E14 -> 0
A15: ='Bilan ouverture'!A19 -> 1020 | B15: ='Bilan ouverture'!B19 -> Banque | C15: =SUMIF(Journal!$C$4:$C$215,A15,Journal!$E$4:$E$215) -> 0 | E15: =SUMIF(Journal!$D$4:$D$215,A15,Journal!$E$4:$E$215) -> 0 | F15: =C15-E15 -> 0
A16: ='Bilan ouverture'!A20 -> 1300 | B16: ='Bilan ouverture'!B20 -> Actifs transitoires | C16: =SUMIF(Journal!$C$4:$C$215,A16,Journal!$E$4:$E$215) -> 0 | E16: =SUMIF(Journal!$D$4:$D$215,A16,Journal!$E$4:$E$215) -> 0 | F16: =C16-E16 -> 0
A17: ='Bilan ouverture'!A21 -> 1110 | B17: ='Bilan ouverture'!B21 -> Cotisation en attente des membres | C17: =SUMIF(Journal!$C$4:$C$215,A17,Journal!$E$4:$E$215) -> 0 | E17: =SUMIF(Journal!$D$4:$D$215,A17,Journal!$E$4:$E$215) -> 0 | F17: =C17-E17 -> 0
A18: ='Bilan ouverture'!A22 -> 1208 | B18: ='Bilan ouverture'!B22 -> Diverses cautions versées | C18: =SUMIF(Journal!$C$4:$C$215,A18,Journal!$E$4:$E$215) -> 0 | E18: =SUMIF(Journal!$D$4:$D$215,A18,Journal!$E$4:$E$215) -> 0 | F18: =C18-E18 -> 0
A19: ='Bilan ouverture'!A23 -> 1500 | B19: ='Bilan ouverture'!B23 -> Actifs ex meuble | C19: =SUMIF(Journal!$C$4:$C$215,A19,Journal!$E$4:$E$215) -> 0 | E19: =SUMIF(Journal!$D$4:$D$215,A19,Journal!$E$4:$E$215) -> 0 | F19: =C19-E19 -> 0
A20: ='Bilan ouverture'!A24 -> 1530 | B20: ='Bilan ouverture'!B24 -> Actifs ex véhicule | C20: =SUMIF(Journal!$C$4:$C$215,A20,Journal!$E$4:$E$215) -> 0 | E20: =SUMIF(Journal!$D$4:$D$215,A20,Journal!$E$4:$E$215) -> 0 | F20: =C20-E20 -> 0
A21: ='Bilan ouverture'!A25 -> 2010 | B21: ='Bilan ouverture'!B25 -> Charges à payer et avance à rembourser | C21: =SUMIF(Journal!$C$4:$C$215,A21,Journal!$E$4:$E$215) -> 0 | E21: =SUMIF(Journal!$D$4:$D$215,A21,Journal!$E$4:$E$215) -> 0 | F21: =C21-E21 -> 0
A22: ='Bilan ouverture'!A26 -> 2400 | B22: ='Bilan ouverture'!B26 -> Dettes bancaires ou autres emprunts | C22: =SUMIF(Journal!$C$4:$C$215,A22,Journal!$E$4:$E$215) -> 0 | E22: =SUMIF(Journal!$D$4:$D$215,A22,Journal!$E$4:$E$215) -> 0 | F22: =C22-E22 -> 0
A23: ='Bilan ouverture'!A27 -> 2300 | B23: ='Bilan ouverture'!B27 -> Passifs transitoires | C23: =SUMIF(Journal!$C$4:$C$215,A23,Journal!$E$4:$E$215) -> 0 | E23: =SUMIF(Journal!$D$4:$D$215,A23,Journal!$E$4:$E$215) -> 0 | F23: =C23-E23 -> 0
A24: ='Bilan ouverture'!A28 -> 2950 | B24: ='Bilan ouverture'!B28 -> Résultat reporté | C24: =SUMIF(Journal!$C$4:$C$215,A24,Journal!$E$4:$E$215) -> 0 | E24: =SUMIF(Journal!$D$4:$D$215,A24,Journal!$E$4:$E$215) -> 0 | F24: =C24-E24 -> 0
A25: ='Bilan ouverture'!A29 -> 9000 | B25: ='Bilan ouverture'!B29 -> Résultat | C25: =SUMIF(Journal!$C$4:$C$215,A25,Journal!$E$4:$E$215) -> 0 | E25: =SUMIF(Journal!$D$4:$D$215,A25,Journal!$E$4:$E$215) -> 0 | F25: =C25-E25 -> 0
... A38: ='Bilan ouverture'!A42 -> 657000 | B38: ='Bilan ouverture'!B42 -> Frais et charges financiers | C38: =SUMIF(Journal!$C$4:$C$215,A38,Journal!$E$4:$E$215) -> 77.32 | E38: =SUMIF(Journal!$D$4:$D$215,A38,Journal!$E$4:$E$215) -> 0 | F38: =C38-E38 -> 77.32
A39: ='Bilan ouverture'!A44 -> 3201 | B39: ='Bilan ouverture'!B44 -> Subventions obtenues projet 1 | C39: =SUMIF(Journal!$C$4:$C$215,A39,Journal!$E$4:$E$215) -> 0 | E39: =SUMIF(Journal!$D$4:$D$215,A39,Journal!$E$4:$E$215) -> 0 | F39: =C39-E39 -> 0
A40: ='Bilan ouverture'!A45 -> 3202 | B40: ='Bilan ouverture'!B45 -> Subventions obtenues projet 2 | C40: =SUMIF(Journal!$C$4:$C$215,A40,Journal!$E$4:$E$215) -> 0 | E40: =SUMIF(Journal!$D$4:$D$215,A40,Journal!$E$4:$E$215) -> 0 | F40: =C40-E40 -> 0
A41: ='Bilan ouverture'!A46 -> 3203 | B41: ='Bilan ouverture'!B46 -> Subventions obtenues projet 3 | C41: =SUMIF(Journal!$C$4:$C$215,A41,Journal!$E$4:$E$215) -> 0 | E41: =SUMIF(Journal!$D$4:$D$215,A41,Journal!$E$4:$E$215) -> 0 | F41: =C41-E41 -> 0
A42: ='Bilan ouverture'!A47 -> 3400 | B42: ='Bilan ouverture'!B47 -> Subventions non affectées obtenues | C42: =SUMIF(Journal!$C$4:$C$215,A42,Journal!$E$4:$E$215) -> 0 | E42: =SUMIF(Journal!$D$4:$D$215,A42,Journal!$E$4:$E$215) -> 0 | F42: =C42-E42 -> 0
A43: ='Bilan ouverture'!A48 -> 3600 | B43: ='Bilan ouverture'!B48 -> Cotisations payées par les membres | C43: =SUMIF(Journal!$C$4:$C$215,A43,Journal!$E$4:$E$215) -> 0 | E43: =SUMIF(Journal!$D$4:$D$215,A43,Journal!$E$4:$E$215) -> 0 | F43: =C43-E43 -> 0
A44: ='Bilan ouverture'!A49 -> 3630 | B44: ='Bilan ouverture'!B49 -> Dons et legs obtenus / boni de caisse | C44: =SUMIF(Journal!$C$4:$C$215,A44,Journal!$E$4:$E$215) -> 0 | E44: =SUMIF(Journal!$D$4:$D$215,A44,Journal!$E$4:$E$215) -> 0 | F44: =C44-E44 -> 0
A45: ='Bilan ouverture'!A50 -> 700000 | B45: ='Bilan ouverture'!B50 -> Paiement Parents | C45: =SUMIF(Journal!$C$4:$C$215,A45,Journal!$E$4:$E$215) -> 0 | E45: =SUMIF(Journal!$D$4:$D$215,A45,Journal!$E$4:$E$215) -> 74789.5
B46: TOTAUX | C46: =SUM(C14:C45) -> 74933.8 | E46: =SUM(E14:E45) -> 74789.5
A50: =A4 -> 1000 | B50: =B4 -> Caisse | C50: =C4 -> 0
A51: =A5 -> 1020 | B51: =B5 -> Banque | C51: =C5 -> 0
A52: =A6 -> 1300 | B52: =B6 -> Actifs transitoires | C52: =C6 -> 0
A53: =A7 -> 1110 | B53: =B7 -> Cotisation en attente des membres | C53: =C7 -> 0
A54: =A8 -> 1208 | B54: =B8 -> Diverses cautions versées | C54: =C8 -> 0
A55: =A9 -> 1500 | B55: =B9 -> Actifs ex meuble | C55: =C9 -> 0
A56: =A10 -> 1530 | B56: =B10 -> Actifs ex véhicule | C56: =C10 -> 0
A57: =D4 -> 2010 | B57: =E4 -> Charges à payer et avance à rembourser | C57: =F4 -> 0
A58: =D5 -> 2400 | B58: =E5 -> Dettes bancaires ou autres emprunts | C58: =F5 -> 0
...

Sheet Budget
B1: Budget pour N+1
B3: Charges | C3: Montants | E3: Produits | F3: Montants
A5: 5200 | B5: Défraiement bénévoles
A6: 5270 | B6: Charges de projet | C6: 0
A7: 6000 | B7: Charges de projet | C7: 0
A8: 6100 | B8: Charges de projet
A9: 6280 | B9: Frais d'expéditions et Pub | C9: 0
A10: 6300 | B10: Divers assurances | C10: 0
A11: 6400 | B11: Electricite, gaz | D11: 3201 | E11: Subventions à obtenir projet | F11: 0
A12: 6500 | B12: Divers frais administratifs | C12: 0 | D12: 3202 | E12: Subventions à obtenir projet | F12: 0
A13: 6640 | B13: Frais de déplacement et recherche | D13: 3203 | E13: Subventions à obtenir projet
A14: 6700 | B14: ACE / mali de caisse | D14: 3400 | E14: Subventions non affectées à obtenir | F14: 0
A15: 6800 | B15: Amortissement actifs | C15: 0 | D15: 3600 | E15: Cotisations payés par les membres | F15: 0
A16: 6900 | B16: Frais et charges financiers | C16: 0 | D16: 3630 | E16: Dons et legs obtenues / boni de caisse
A17: 9000 | B17: Résultat avant affectation | C17: =SUM(F11:F17)-SUM(C5:C16) -> 0 | D17: 6950 | E17: Intérêts bancaires produits | F17: 0
B18: Total | C18: =SUM(C5:C17) -> 0 | E18: Total | F18: =SUM(F9:F17) -> 0
C21: Amortisement des actifs
B22: Amortissement linéaire au prorata -temporis
B24: Valeur actif | D24: 0 | E24: taux | F24: 0
B25: Date de mise en service | C25: 44562 | D25: date de clôture | E25: 46752 | F25: 0
B26: Année | C26: taux | D26: Amortissement | E26: cumul | F26: Valeur résiduel
B27: 2017 | C27: =F24 -> 0 | D27: =D24*C27*F25/360 -> 0 | E27: =D27 -> 0 | F27: =D24-D27 -> 0
B28: 2018 | C28: =C27 -> 0 | D28: 20000 | E28: =E27+D28 -> 20000 | F28: =F27-D28 -> -20000
B29: 2019 | C29: =C28 -> 0 | D29: =D28 -> 20000 | E29: =E28+D29 -> 40000 | F29: =F28-D29 -> -40000
B30: 2020 | C30: =C29 -> 0 | D30: =D29 -> 20000 | E30: =E29+D30 -> 60000 | F30: =F29-D30 -> -60000
B31: 2021 | C31: =C30 -> 0 | D31: =D30 +(20000-D27)-1 -> 39999 | E31: =E30+D31 -> 99999 | F31: =F30-D31 -> -99999
B32: Enregistrement au tableur
B33: =A15 -> 6800 | C33: =B15 -> Amortissement actifs | D33: à | E33: Actif | F33: =D27 -> 0
B36: Amortissement dégressif du même actif
B37: Valeur actif | D37: =D24 -> 0 | E37: taux | F37: 0.4
B38: Année | C38: taux | D38: amortissement | E38: cummul | F38: Valeur résiduel
B39: 2017 | C39: =F37 -> 0.4 | D39: =D37*C39 -> 0 | E39: =D39 -> 0 | F39: =D37-D39 -> 0
B40: 2018 | C40: =C39 -> 0.4 | D40: =F39*C40 -> 0 | E40: =E39+D40 -> 0 | F40: =F39-D40 -> 0
B41: 2019 | C41: =C40 -> 0.4 | D41: =F40*C41 -> 0 | E41: =E40+D41 -> 0 | F41: =F40-D41 -> 0
B42: 2020 | C42: =C41 -> 0.4 | D42: =F41*C42 -> 0 | E42: =E41+D42 -> 0 | F42: =F41-D42 -> 0
B43: 2021 | C43: =C42 -> 0.4 | D43: =F42-1 -> -1 | E43: =E42+D43 -> -1 | F43: =F42-D43 -> 1
B44: Enregistrement au tableur
B45: =B33 -> 6800 | C45: =C33 -> Amortissement actifs | D45: à | E45: Actif | F45: =D39 -> 0
D48: Amortisement financier
B49: Amortissement financier en cas d'emprunt
...

Sheet Imprimer
A1: Bilan 2024 - FOOT FUN FAMILY FFF BE0721643871
A3: ='Bilan Clôture'!A2 -> 0 | B3: ='Bilan Clôture'!B2 -> Actifs | C3: ='Bilan Clôture'!C2 -> Montant | D3: ='Bilan Clôture'!D2 -> 0 | E3: ='Bilan Clôture'!E2 -> Passifs | F3: ='Bilan Clôture'!F2 -> Montant
A4: ='Bilan Clôture'!A3 -> N0 | B4: ='Bilan Clôture'!B3 -> Comptes | C4: ='Bilan Clôture'!C3 -> 0 | D4: ='Bilan Clôture'!D3 -> N0 | E4: ='Bilan Clôture'!E3 -> Comptes | F4: ='Bilan Clôture'!F3 -> 0
A5: ='Bilan Clôture'!A4 -> 1000 | B5: ='Bilan Clôture'!B4 -> Caisse | C5: ='Bilan Clôture'!C4 -> 0 | D5: ='Bilan Clôture'!D4 -> 2010 | E5: ='Bilan Clôture'!E4 -> Charges à payer et avance à rembourser | F5: ='Bilan Clôture'!F4 -> 0
A6: ='Bilan Clôture'!A5 -> 1020 | B6: ='Bilan Clôture'!B5 -> Banque | C6: 1399.23 | D6: ='Bilan Clôture'!D5 -> 2400 | E6: ='Bilan Clôture'!E5 -> Dettes bancaires ou autres emprunts | F6: ='Bilan Clôture'!F5 -> 0
A7: ='Bilan Clôture'!A6 -> 1300 | B7: ='Bilan Clôture'!B6 -> Actifs transitoires | C7: ='Bilan Clôture'!C6 -> 0 | D7: ='Bilan Clôture'!D6 -> 2300 | E7: ='Bilan Clôture'!E6 -> Passifs transitoires | F7: ='Bilan Clôture'!F6 -> 0
A8: ='Bilan Clôture'!A7 -> 1110 | B8: ='Bilan Clôture'!B7 -> Cotisation en attente des membres | C8: ='Bilan Clôture'!C7 -> 0 | D8: ='Bilan Clôture'!D7 -> 2950 | E8: ='Bilan Clôture'!E7 -> Résultat reporté | F8: ='Bilan Clôture'!F7 -> 0
A9: ='Bilan Clôture'!A8 -> 1208 | B9: ='Bilan Clôture'!B8 -> Diverses cautions versées | C9: ='Bilan Clôture'!C8 -> 0 | D9: ='Bilan Clôture'!D8 -> 9000 | E9: ='Bilan Clôture'!E8 -> Résultat | F9: ='Bilan Clôture'!F8 -> 0
A10: ='Bilan Clôture'!A9 -> 1500 | B10: ='Bilan Clôture'!B9 -> Actifs ex meuble | C10: ='Bilan Clôture'!C9 -> 0 | D10: ='Bilan Clôture'!D9 -> 2800 | E10: ='Bilan Clôture'!E9 -> Capital ou fond déposé en banque | F10: ='Bilan Clôture'!F9 -> 0
A11: ='Bilan Clôture'!A10 -> 1530 | B11: ='Bilan Clôture'!B10 -> Actifs ex véhicule | C11: ='Bilan Clôture'!C10 -> 0
B12: ='Bilan Clôture'!B11 -> Total | C12: =C6 -> 1399.23 | E12: ='Bilan Clôture'!E11 -> Total | F12: ='Bilan Clôture'!F11 -> 0
A14: Compte d'exploitation ou Résultat
B16: =Résultat!B4 -> Charges | C16: =Résultat!C4 -> Montants | E16: =Résultat!E4 -> Produits | F16: =Résultat!F4 -> Montants
A17: =Résultat!A6 -> 454000 | B17: =Résultat!B6 -> Frais bénévoles PP ONSS | C17: =Résultat!C6 -> 0 | F17: =Résultat!F6 -> 0
A18: =Résultat!A7 -> 611000 | B18: =Résultat!B7 -> Loyer | C18: =Résultat!C7 -> 7167.5 | F18: =Résultat!F7 -> 0
A19: =Résultat!A8 -> 611100 | B19: =Résultat!B8 -> Electricité, gaz | C19: =Résultat!C8 -> 0 | F19: =Résultat!F8 -> 0
A20: =Résultat!A9 -> 611200 | B20: =Résultat!B9 -> Charges Divers | C20: =Résultat!C9 -> 59688.68 | F20: =Résultat!F9 -> 0
A21: =Résultat!A10 -> 611500 | B21: =Résultat!B10 -> Frais d'expéditions et Pub | C21: =Résultat!C10 -> 0 | F21: =Résultat!F10 -> 0
A22: =Résultat!A11 -> 614000 | B22: =Résultat!B11 -> Divers assurances | C22: =Résultat!C11 -> 0 | F22: =Résultat!F11 -> 0
A23: =Résultat!A12 -> 621000 | B23: =Résultat!B12 -> Salaire | C23: =Résultat!C12 -> 8000.3 | D23: =Résultat!D12 -> 3201 | E23: =Résultat!E12 -> Subventions obtenues projet 1 | F23: =Résultat!F12 -> 0
A24: =Résultat!A13 -> 613000 | B24: =Résultat!B13 -> Divers frais administratifs | C24: =Résultat!C13 -> 0 | D24: =Résultat!D13 -> 3202 | E24: =Résultat!E13 -> Subventions obtenues projet 2 | F24: =Résultat!F13 -> 0
A25: =Résultat!A14 -> 618000 | B25: =Résultat!B14 -> Frais Bénévoles | C25: =Résultat!C14 -> 0 | D25: =Résultat!D14 -> 3203 | E25: =Résultat!E14 -> Subventions obtenues projet 3 | F25: =Résultat!F14 -> 0
A26: =Résultat!A15 -> 670000 | B26: =Résultat!B15 -> ACE / mali de caisse | C26: =Résultat!C15 -> 0 | D26: =Résultat!D15 -> 3400 | E26: =Résultat!E15 -> Subventions non affectées obtenues | F26: =Résultat!F15 -> 0
A27: =Résultat!A16 -> 630000 | B27: =Résultat!B16 -> Amortissement actifs | C27: =Résultat!C16 -> 0 | D27: =Résultat!D16 -> 3600 | E27: =Résultat!E16 -> Cotisations payées par les membres | F27: =Résultat!F16 -> 0
A28: =Résultat!A17 -> 657000 | B28: =Résultat!B17 -> Frais et charges financiers | C28: =Résultat!C17 -> 77.32 | D28: =Résultat!D17 -> 3630 | E28: =Résultat!E17 -> Dons et legs obtenus / boni de caisse | F28: =Résultat!F17 -> 0
A29: =Résultat!A18 -> 140000 | B29: =Résultat!B18 -> Résultat avant affectation | C29: -144.3 | D29: =Résultat!D18 -> 700000 | E29: =Résultat!E18 -> Paiement Parents | F29: =Journal!E18 -> 74789.5
B30: =Résultat!B19 -> Total | C30: =SUM(C17:C29) -> 74789.5 | E30: Total | F30: =SUM(F28:F29) -> 74789.5
B33: Budget pour N+1
B35: Charges | C35: Montants | E35: Produits | F35: Montants
A37: =Budget!A5 -> 5200 | B37: =Budget!B5 -> Défraiement bénévoles | C37: =Budget!C5 -> 0
A38: =Budget!A6 -> 5270 | B38: =Budget!B6 -> Charges de projet | C38: =Budget!C6 -> 0
A39: =Budget!A7 -> 6000 | B39: =Budget!B7 -> Charges de projet | C39: =Budget!C7 -> 0
A40: =Budget!A8 -> 6100 | B40: =Budget!B8 -> Charges de projet | C40: =Budget!C8 -> 0
A41: =Budget!A9 -> 6280 | B41: =Budget!B9 -> Frais d'expéditions et Pub | C41: =Budget!C9 -> 0
A42: =Budget!A10 -> 6300 | B42: =Budget!B10 -> Divers assurances | C42: =Budget!C10 -> 0
A43: =Budget!A11 -> 6400 | B43: =Budget!B11 -> Electricite, gaz | C43: =Budget!C11 -> 0 | D43: =Budget!D11 -> 3201 | E43: =Budget!E11 -> Subventions à obtenir projet | F43: =Budget!F11 -> 0
A44: =Budget!A12 -> 6500 | B44: =Budget!B12 -> Divers frais administratifs | C44: =Budget!C12 -> 0 | D44: =Budget!D12 -> 3202 | E44: =Budget!E12 -> Subventions à obtenir projet | F44: =Budget!F12 -> 0
A45: =Budget!A13 -> 6640 | B45: =Budget!B13 -> Frais de déplacement et recherche | C45: =Budget!C13 -> 0 | D45: =Budget!D13 -> 3203 | E45: =Budget!E13 -> Subventions à obtenir projet | F45: =Budget!F13 -> 0
A46: =Budget!A14 -> 6700 | B46: =Budget!B14 -> ACE / mali de caisse | C46: =Budget!C14 -> 0 | D46: =Budget!D14 -> 3400 | E46: =Budget!E14 -> Subventions non affectées à obtenir | F46: =Budget!F14 -> 0
A47: =Budget!A15 -> 6800 | B47: =Budget!B15 -> Amortissement actifs | C47: =Budget!C15 -> 0 | D47: =Budget!D15 -> 3600 | E47: =Budget!E15 -> Cotisations payés par les membres | F47: =Budget!F15 -> 0
...

Sheet Membres
A1: Cotisation des membres et bénévoles
A2: N° | B2: Nom Prénom | C2: Date de paiement | D2: montant | E2: Code Postal | F2: Catégorie | G2: Téléphone | H2: Email
A3: 1
A4: 2
A5: 3
A6: 4
A7: 5
A8: 6
A9: 7
A10: 8
A23: Totaux | D23: =SUM(D3:D22) -> 0
